Workbook

Sheet About
A1: Access to Drinking Water – Transforming the Data (2000–2020)
A2: ALX Africa Data Analytics program · Data: WHO/UNICEF Joint Monitoring Programme (JMP), estimates 2000–2020
A4: Objective
A5: Measure whether access to basic drinking water is improving or declining, and where: national vs rural vs urban populations, and by world region (SDG 6).
A7: Sheets
A8: Data | B8: Two records per country (earliest and latest year) with calculated features.
A9: Summary | B9: Year coverage, ARC statistics, change in access by area, rural vs urban ARC difference.
A10: Regions | B10: Averages and full-access counts per region, plus charts.
A11: Chart Data | B11: Linked values feeding the bubble chart.
A12: Region Lookup | B12: Country → region reference table (imported Regions.csv).
A14: Annual Rate of Change (ARC)
A15: ARC = (access in latest year − access in earliest year) ÷ (number of years between them). Expressed in percentage points per year.
A17: Cleaning & corrections
A18: • Converted numbers stored as text (1,400+ cells) into real numbers.
A19: • Replaced the text "null" with empty cells, so statistics ignore missing values instead of failing.
A20: • Zimbabwe: population written with spaces ("13 815") converted to numbers; urban surface water "<1" set to 0.5.
A21: • ARC difference now keeps its sign (rural − urban) instead of an absolute value, so the histogram shows which area improved faster, and it no longer returns errors.
A22: • Region lookup uses INDEX/MATCH, which works in Excel and Google Sheets.
A25: Column dictionary
A26: Column | B26: Original field / how it is calculated
A27: Country | B27: Original JMP field: name
A28: Region | B28: Original JMP field: (from Regions.csv)
A29: Year | B29: Original JMP field: year
A30: Population (thousands) | B30: Original JMP field: pop_n
A31: Urban population (%) | B31: Original JMP field: pop_u
A32: Basic – national (%) | B32: Original JMP field: wat_bas_n
A33: Limited – national (%) | B33: Original JMP field: wat_lim_n
A34: Unimproved – national (%) | B34: Original JMP field: wat_unimp_n
A35: Surface water – national (%) | B35: Original JMP field: wat_sur_n
A36: Basic – rural (%) | B36: Original JMP field: wat_bas_r
A37: Limited – rural (%) | B37: Original JMP field: wat_lim_r
... A54: ARC difference (rural − urban) | B54: ARC_diff: ARC – rural − ARC – urban
A56: "Basic" = share of people with at least basic service (improved source, ≤ 30 min round trip).

Sheet Data
A1: Country | B1: Region | C1: Year | D1: Population (thousands) | E1: Urban population (%) | F1: Basic – national (%) | G1: Limited – national (%) | H1: Unimproved – national (%) | I1: Surface water – national (%) | J1: Basic – rural (%) | K1: Limited – rural (%) | L1: Unimproved – rural (%) | M1: Surface water – rural (%) | N1: Basic – urban (%) | O1: Limited – urban (%) | P1: Unimproved – urban (%) | Q1: Surface water – urban (%) | R1: Year difference | S1: ARC – national | T1: ARC – rural | U1: ARC – urban | V1: Basic – national (rounded) | W1: Basic – rural (rounded) | X1: Basic – urban (rounded) | Y1: Full access – national | Z1: Full access – rural | AA1: Full access – urban | AB1: ARC difference (rural − urban)
A2: Afghanistan | B2: =IFERROR(INDEX('Region Lookup'!$B$2:$B$233,MATCH(A2,'Region Lookup'!$A$2:$A$233,0)),"Not found") -> South Asia | C2: 2015 | D2: 34413.602 | E2: 24.802999 | F2: 61.339781 | G2: 3.5111995 | H2: 22.168784 | I2: 12.980236 | J2: 52.988502 | K2: 3.8611366 | L2: 26.553268 | M2: 16.597094 | N2: 86.658941 | O2: 2.4502706 | P2: 8.8760357 | Q2: 2.014753 | R2: =IF($A2=$A3,$C3-$C2,"") -> 5 | S2: =IF(AND($A2=$A3,ISNUMBER(F2),ISNUMBER(F3)),(F3-F2)/($C3-$C2),"") -> 2.7503265 | T2: =IF(AND($A2=$A3,ISNUMBER(J2),ISNUMBER(J3)),(J3-J2)/($C3-$C2),"") -> 2.6678826 | U2: =IF(AND($A2=$A3,ISNUMBER(N2),ISNUMBER(N3)),(N3-N2)/($C3-$C2),"") -> 2.6682119 | V2: =IF(ISNUMBER(F2),ROUND(F2,0),"") -> 61 | W2: =IF(ISNUMBER(J2),ROUND(J2,0),"") -> 53 | X2: =IF(ISNUMBER(N2),ROUND(N2,0),"") -> 87 | Y2: =IF(AND($A2=$A3,V2=100,V3=100),"full access","") | Z2: =IF(AND($A2=$A3,W2=100,W3=100),"full access","") | AA2: =IF(AND($A2=$A3,X2=100,X3=100),"full access","") | AB2: =IF(AND(ISNUMBER(T2),ISNUMBER(U2)),T2-U2,"") -> -0.000329218
A3: Afghanistan | B3: =IFERROR(INDEX('Region Lookup'!$B$2:$B$233,MATCH(A3,'Region Lookup'!$A$2:$A$233,0)),"Not found") -> South Asia | C3: 2020 | D3: 38928.34 | E3: 26.025999 | F3: 75.091413 | G3: 1.4475417 | H3: 14.560263 | I3: 8.9007822 | J3: 66.327915 | K3: 1.9568249 | L3: 19.682949 | M3: 12.032311 | N3: 100 | O3: 0 | P3: 0 | Q3: 0 | R3: =IF($A3=$A4,$C4-$C3,"") | S3: =IF(AND($A3=$A4,ISNUMBER(F3),ISNUMBER(F4)),(F4-F3)/($C4-$C3),"") | T3: =IF(AND($A3=$A4,ISNUMBER(J3),ISNUMBER(J4)),(J4-J3)/($C4-$C3),"") | U3: =IF(AND($A3=$A4,ISNUMBER(N3),ISNUMBER(N4)),(N4-N3)/($C4-$C3),"") | V3: =IF(ISNUMBER(F3),ROUND(F3,0),"") -> 75 | W3: =IF(ISNUMBER(J3),ROUND(J3,0),"") -> 66 | X3: =IF(ISNUMBER(N3),ROUND(N3,0),"") -> 100 | Y3: =IF(AND($A3=$A4,V3=100,V4=100),"full access","") | Z3: =IF(AND($A3=$A4,W3=100,W4=100),"full access","") | AA3: =IF(AND($A3=$A4,X3=100,X4=100),"full access","") | AB3: =IF(AND(ISNUMBER(T3),ISNUMBER(U3)),T3-U3,"")
A4: Albania | B4: =IFERROR(INDEX('Region Lookup'!$B$2:$B$233,MATCH(A4,'Region Lookup'!$A$2:$A$233,0)),"Not found") -> Europe & Central Asia | C4: 2015 | D4: 2890.5239 | E4: 57.433998 | F4: 93.394325 | G4: 3.6263837 | H4: 2.979291 | I4: 0 | J4: 90.627275 | K4: 5.2631726 | L4: 4.1095527 | M4: 0 | N4: 95.445067 | O4: 2.4133118 | P4: 2.1416212 | Q4: 0 | R4: =IF($A4=$A5,$C5-$C4,"") -> 5 | S4: =IF(AND($A4=$A5,ISNUMBER(F4),ISNUMBER(F5)),(F5-F4)/($C5-$C4),"") -> 0.3347427 | T4: =IF(AND($A4=$A5,ISNUMBER(J4),ISNUMBER(J5)),(J5-J4)/($C5-$C4),"") -> 0.69281669 | U4: =IF(AND($A4=$A5,ISNUMBER(N4),ISNUMBER(N5)),(N5-N4)/($C5-$C4),"") -> 0.043748432 | V4: =IF(ISNUMBER(F4),ROUND(F4,0),"") -> 93 | W4: =IF(ISNUMBER(J4),ROUND(J4,0),"") -> 91 | X4: =IF(ISNUMBER(N4),ROUND(N4,0),"") -> 95 | Y4: =IF(AND($A4=$A5,V4=100,V5=100),"full access","") | Z4: =IF(AND($A4=$A5,W4=100,W5=100),"full access","") | AA4: =IF(AND($A4=$A5,X4=100,X5=100),"full access","") | AB4: =IF(AND(ISNUMBER(T4),ISNUMBER(U4)),T4-U4,"") -> 0.64906826
A5: Albania | B5: =IFERROR(INDEX('Region Lookup'!$B$2:$B$233,MATCH(A5,'Region Lookup'!$A$2:$A$233,0)),"Not found") -> Europe & Central Asia | C5: 2020 | D5: 2877.8 | E5: 62.112 | F5: 95.068039 | G5: 1.8846561 | H5: 3.0473051 | I5: 0 | J5: 94.091358 | K5: 2.305265 | L5: 3.603377 | M5: 0 | N5: 95.663809 | O5: 1.6280868 | P5: 2.7081041 | Q5: 0 | R5: =IF($A5=$A6,$C6-$C5,"") | S5: =IF(AND($A5=$A6,ISNUMBER(F5),ISNUMBER(F6)),(F6-F5)/($C6-$C5),"") | T5: =IF(AND($A5=$A6,ISNUMBER(J5),ISNUMBER(J6)),(J6-J5)/($C6-$C5),"") | U5: =IF(AND($A5=$A6,ISNUMBER(N5),ISNUMBER(N6)),(N6-N5)/($C6-$C5),"") | V5: =IF(ISNUMBER(F5),ROUND(F5,0),"") -> 95 | W5: =IF(ISNUMBER(J5),ROUND(J5,0),"") -> 94 | X5: =IF(ISNUMBER(N5),ROUND(N5,0),"") -> 96 | Y5: =IF(AND($A5=$A6,V5=100,V6=100),"full access","") | Z5: =IF(AND($A5=$A6,W5=100,W6=100),"full access","") | AA5: =IF(AND($A5=$A6,X5=100,X6=100),"full access","") | AB5: =IF(AND(ISNUMBER(T5),ISNUMBER(U5)),T5-U5,"")
A6: Algeria | B6: =IFERROR(INDEX('Region Lookup'!$B$2:$B$233,MATCH(A6,'Region Lookup'!$A$2:$A$233,0)),"Not found") -> Middle East & North Africa | C6: 2015 | D6: 39728.02 | E6: 70.848 | F6: 93.409562 | G6: 5.1577809 | H6: 1.2754647 | I6: 0.15719289 | J6: 88.352707 | K6: 8.6857531 | L6: 2.5804318 | M6: 0.38110822 | N6: 95.490315 | O6: 3.7061173 | P6: 0.73851009 | Q6: 0.065057898 | R6: =IF($A6=$A7,$C7-$C6,"") -> 5 | S6: =IF(AND($A6=$A7,ISNUMBER(F6),ISNUMBER(F7)),(F7-F6)/($C7-$C6),"") -> 0.20555369 | T6: =IF(AND($A6=$A7,ISNUMBER(J6),ISNUMBER(J7)),(J7-J6)/($C7-$C6),"") -> 0.33696621 | U6: =IF(AND($A6=$A7,ISNUMBER(N6),ISNUMBER(N7)),(N7-N6)/($C7-$C6),"") -> 0.10288423 | V6: =IF(ISNUMBER(F6),ROUND(F6,0),"") -> 93 | W6: =IF(ISNUMBER(J6),ROUND(J6,0),"") -> 88 | X6: =IF(ISNUMBER(N6),ROUND(N6,0),"") -> 95 | Y6: =IF(AND($A6=$A7,V6=100,V7=100),"full access","") | Z6: =IF(AND($A6=$A7,W6=100,W7=100),"full access","") | AA6: =IF(AND($A6=$A7,X6=100,X7=100),"full access","") | AB6: =IF(AND(ISNUMBER(T6),ISNUMBER(U6)),T6-U6,"") -> 0.23408198
A7: Algeria | B7: =IFERROR(INDEX('Region Lookup'!$B$2:$B$233,MATCH(A7,'Region Lookup'!$A$2:$A$233,0)),"Not found") -> Middle East & North Africa | C7: 2020 | D7: 43851.043 | E7: 73.733002 | F7: 94.43733 | G7: 4.9858808 | H7: 0.53183666 | I7: 0.044952533 | J7: 90.037538 | K7: 8.7967221 | L7: 0.99460303 | M7: 0.17113693 | N7: 96.004736 | O7: 3.6282886 | P7: 0.36697555 | Q7: 0 | R7: =IF($A7=$A8,$C8-$C7,"") | S7: =IF(AND($A7=$A8,ISNUMBER(F7),ISNUMBER(F8)),(F8-F7)/($C8-$C7),"") | T7: =IF(AND($A7=$A8,ISNUMBER(J7),ISNUMBER(J8)),(J8-J7)/($C8-$C7),"") | U7: =IF(AND($A7=$A8,ISNUMBER(N7),ISNUMBER(N8)),(N8-N7)/($C8-$C7),"") | V7: =IF(ISNUMBER(F7),ROUND(F7,0),"") -> 94 | W7: =IF(ISNUMBER(J7),ROUND(J7,0),"") -> 90 | X7: =IF(ISNUMBER(N7),ROUND(N7,0),"") -> 96 | Y7: =IF(AND($A7=$A8,V7=100,V8=100),"full access","") | Z7: =IF(AND($A7=$A8,W7=100,W8=100),"full access","") | AA7: =IF(AND($A7=$A8,X7=100,X8=100),"full access","") | AB7: =IF(AND(ISNUMBER(T7),ISNUMBER(U7)),T7-U7,"")
A8: American Samoa | B8: =IFERROR(INDEX('Region Lookup'!$B$2:$B$233,MATCH(A8,'Region Lookup'!$A$2:$A$233,0)),"Not found") -> East Asia & Pacific | C8: 2015 | D8: 55.806 | E8: 87.238007 | F8: 99.619103 | G8: 0 | H8: 0.38089685 | I8: 0 | R8: =IF($A8=$A9,$C9-$C8,"") -> 5 | S8: =IF(AND($A8=$A9,ISNUMBER(F8),ISNUMBER(F9)),(F9-F8)/($C9-$C8),"") -> 0.030933702 | T8: =IF(AND($A8=$A9,ISNUMBER(J8),ISNUMBER(J9)),(J9-J8)/($C9-$C8),"") | U8: =IF(AND($A8=$A9,ISNUMBER(N8),ISNUMBER(N9)),(N9-N8)/($C9-$C8),"") | V8: =IF(ISNUMBER(F8),ROUND(F8,0),"") -> 100 | W8: =IF(ISNUMBER(J8),ROUND(J8,0),"") | X8: =IF(ISNUMBER(N8),ROUND(N8,0),"") | Y8: =IF(AND($A8=$A9,V8=100,V9=100),"full access","") -> full access | Z8: =IF(AND($A8=$A9,W8=100,W9=100),"full access","") | AA8: =IF(AND($A8=$A9,X8=100,X9=100),"full access","") | AB8: =IF(AND(ISNUMBER(T8),ISNUMBER(U8)),T8-U8,"")
A9: American Samoa | B9: =IFERROR(INDEX('Region Lookup'!$B$2:$B$233,MATCH(A9,'Region Lookup'!$A$2:$A$233,0)),"Not found") -> East Asia & Pacific | C9: 2020 | D9: 55.196999 | E9: 87.153 | F9: 99.773772 | G9: 0 | H9: 0.22622834 | I9: 0 | R9: =IF($A9=$A10,$C10-$C9,"") | S9: =IF(AND($A9=$A10,ISNUMBER(F9),ISNUMBER(F10)),(F10-F9)/($C10-$C9),"") | T9: =IF(AND($A9=$A10,ISNUMBER(J9),ISNUMBER(J10)),(J10-J9)/($C10-$C9),"") | U9: =IF(AND($A9=$A10,ISNUMBER(N9),ISNUMBER(N10)),(N10-N9)/($C10-$C9),"") | V9: =IF(ISNUMBER(F9),ROUND(F9,0),"") -> 100 | W9: =IF(ISNUMBER(J9),ROUND(J9,0),"") | X9: =IF(ISNUMBER(N9),ROUND(N9,0),"") | Y9: =IF(AND($A9=$A10,V9=100,V10=100),"full access","") | Z9: =IF(AND($A9=$A10,W9=100,W10=100),"full access","") | AA9: =IF(AND($A9=$A10,X9=100,X10=100),"full access","") | AB9: =IF(AND(ISNUMBER(T9),ISNUMBER(U9)),T9-U9,"")
A10: Andorra | B10: =IFERROR(INDEX('Region Lookup'!$B$2:$B$233,MATCH(A10,'Region Lookup'!$A$2:$A$233,0)),"Not found") -> Europe & Central Asia | C10: 2015 | D10: 77.992996 | E10: 88.344994 | F10: 99.999998 | G10: 0 | H10: 2.4455384e-06 | I10: 0 | J10: 100 | K10: 0 | L10: 0 | M10: 0 | N10: 100 | O10: 0 | P10: 0 | Q10: 0 | R10: =IF($A10=$A11,$C11-$C10,"") -> 5 | S10: =IF(AND($A10=$A11,ISNUMBER(F10),ISNUMBER(F11)),(F11-F10)/($C11-$C10),"") -> 1.23e-06 | T10: =IF(AND($A10=$A11,ISNUMBER(J10),ISNUMBER(J11)),(J11-J10)/($C11-$C10),"") -> 0 | U10: =IF(AND($A10=$A11,ISNUMBER(N10),ISNUMBER(N11)),(N11-N10)/($C11-$C10),"") -> 0 | V10: =IF(ISNUMBER(F10),ROUND(F10,0),"") -> 100 | W10: =IF(ISNUMBER(J10),ROUND(J10,0),"") -> 100 | X10: =IF(ISNUMBER(N10),ROUND(N10,0),"") -> 100 | Y10: =IF(AND($A10=$A11,V10=100,V11=100),"full access","") -> full access | Z10: =IF(AND($A10=$A11,W10=100,W11=100),"full access","") -> full access | AA10: =IF(AND($A10=$A11,X10=100,X11=100),"full access","") -> full access | AB10: =IF(AND(ISNUMBER(T10),ISNUMBER(U10)),T10-U10,"") -> 0
A11: Andorra | B11: =IFERROR(INDEX('Region Lookup'!$B$2:$B$233,MATCH(A11,'Region Lookup'!$A$2:$A$233,0)),"Not found") -> Europe & Central Asia | C11: 2020 | D11: 77.264999 | E11: 87.916 | F11: 100 | G11: 0 | H11: 0 | I11: 0 | J11: 100 | K11: 0 | L11: 0 | M11: 0 | N11: 100 | O11: 0 | P11: 0 | Q11: 0 | R11: =IF($A11=$A12,$C12-$C11,"") | S11: =IF(AND($A11=$A12,ISNUMBER(F11),ISNUMBER(F12)),(F12-F11)/($C12-$C11),"") | T11: =IF(AND($A11=$A12,ISNUMBER(J11),ISNUMBER(J12)),(J12-J11)/($C12-$C11),"") | U11: =IF(AND($A11=$A12,ISNUMBER(N11),ISNUMBER(N12)),(N12-N11)/($C12-$C11),"") | V11: =IF(ISNUMBER(F11),ROUND(F11,0),"") -> 100 | W11: =IF(ISNUMBER(J11),ROUND(J11,0),"") -> 100 | X11: =IF(ISNUMBER(N11),ROUND(N11,0),"") -> 100 | Y11: =IF(AND($A11=$A12,V11=100,V12=100),"full access","") | Z11: =IF(AND($A11=$A12,W11=100,W12=100),"full access","") | AA11: =IF(AND($A11=$A12,X11=100,X12=100),"full access","") | AB11: =IF(AND(ISNUMBER(T11),ISNUMBER(U11)),T11-U11,"")
A12: Angola | B12: =IFERROR(INDEX('Region Lookup'!$B$2:$B$233,MATCH(A12,'Region Lookup'!$A$2:$A$233,0)),"Not found") -> Sub-Saharan Africa | C12: 2015 | D12: 27884.381 | E12: 63.445995 | F12: 54.316928 | G12: 11.368619 | H12: 17.372356 | I12: 16.942097 | J12: 26.714369 | K12: 9.9310693 | L12: 21.725308 | M12: 41.629254 | N12: 70.219965 | O12: 12.196853 | P12: 14.864431 | Q12: 2.7187499 | R12: =IF($A12=$A13,$C13-$C12,"") -> 5 | S12: =IF(AND($A12=$A13,ISNUMBER(F12),ISNUMBER(F13)),(F13-F12)/($C13-$C12),"") -> 0.57016185 | T12: =IF(AND($A12=$A13,ISNUMBER(J12),ISNUMBER(J13)),(J13-J12)/($C13-$C12),"") -> 0.21877144 | U12: =IF(AND($A12=$A13,ISNUMBER(N12),ISNUMBER(N13)),(N13-N12)/($C13-$C12),"") -> 0.3046367 | V12: =IF(ISNUMBER(F12),ROUND(F12,0),"") -> 54 | W12: =IF(ISNUMBER(J12),ROUND(J12,0),"") -> 27 | X12: =IF(ISNUMBER(N12),ROUND(N12,0),"") -> 70 | Y12: =IF(AND($A12=$A13,V12=100,V13=100),"full access","") | Z12: =IF(AND($A12=$A13,W12=100,W13=100),"full access","") | AA12: =IF(AND($A12=$A13,X12=100,X13=100),"full access","") | AB12: =IF(AND(ISNUMBER(T12),ISNUMBER(U12)),T12-U12,"") -> -0.085865258
A13: Angola | B13: =IFERROR(INDEX('Region Lookup'!$B$2:$B$233,MATCH(A13,'Region Lookup'!$A$2:$A$233,0)),"Not found") -> Sub-Saharan Africa | C13: 2020 | D13: 32866.27 | E13: 66.824997 | F13: 57.167738 | G13: 9.2873499 | H13: 19.450825 | I13: 14.094087 | J13: 27.808227 | K13: 8.7404884 | L13: 22.933153 | M13: 40.518132 | N13: 71.743149 | O13: 9.5588375 | P13: 17.722035 | Q13: 0.97597916 | R13: =IF($A13=$A14,$C14-$C13,"") | S13: =IF(AND($A13=$A14,ISNUMBER(F13),ISNUMBER(F14)),(F14-F13)/($C14-$C13),"") | T13: =IF(AND($A13=$A14,ISNUMBER(J13),ISNUMBER(J14)),(J14-J13)/($C14-$C13),"") | U13: =IF(AND($A13=$A14,ISNUMBER(N13),ISNUMBER(N14)),(N14-N13)/($C14-$C13),"") | V13: =IF(ISNUMBER(F13),ROUND(F13,0),"") -> 57 | W13: =IF(ISNUMBER(J13),ROUND(J13,0),"") -> 28 | X13: =IF(ISNUMBER(N13),ROUND(N13,0),"") -> 72 | Y13: =IF(AND($A13=$A14,V13=100,V14=100),"full access","") | Z13: =IF(AND($A13=$A14,W13=100,W14=100),"full access","") | AA13: =IF(AND($A13=$A14,X13=100,X14=100),"full access","") | AB13: =IF(AND(ISNUMBER(T13),ISNUMBER(U13)),T13-U13,"")
A14: Anguilla | B14: =IFERROR(INDEX('Region Lookup'!$B$2:$B$233,MATCH(A14,'Region Lookup'!$A$2:$A$233,0)),"Not found") -> Latin America & Caribbean | C14: 2015 | D14: 14.279 | E14: 100 | F14: 97.482274 | G14: 0 | H14: 2.5177258 | I14: 0 | N14: 97.482274 | O14: 0 | P14: 2.5177258 | Q14: 0 | R14: =IF($A14=$A15,$C15-$C14,"") -> 2 | S14: =IF(AND($A14=$A15,ISNUMBER(F14),ISNUMBER(F15)),(F15-F14)/($C15-$C14),"") -> 0 | T14: =IF(AND($A14=$A15,ISNUMBER(J14),ISNUMBER(J15)),(J15-J14)/($C15-$C14),"") | U14: =IF(AND($A14=$A15,ISNUMBER(N14),ISNUMBER(N15)),(N15-N14)/($C15-$C14),"") -> 0 | V14: =IF(ISNUMBER(F14),ROUND(F14,0),"") -> 97 | W14: =IF(ISNUMBER(J14),ROUND(J14,0),"") | X14: =IF(ISNUMBER(N14),ROUND(N14,0),"") -> 97 | Y14: =IF(AND($A14=$A15,V14=100,V15=100),"full access","") | Z14: =IF(AND($A14=$A15,W14=100,W15=100),"full access","") | AA14: =IF(AND($A14=$A15,X14=100,X15=100),"full access","") | AB14: =IF(AND(ISNUMBER(T14),ISNUMBER(U14)),T14-U14,"")
A15: Anguilla | B15: =IFERROR(INDEX('Region Lookup'!$B$2:$B$233,MATCH(A15,'Region Lookup'!$A$2:$A$233,0)),"Not found") -> Latin America & Caribbean | C15: 2017 | D15: 14.588 | E15: 100 | F15: 97.482274 | G15: 0 | H15: 2.5177258 | I15: 0 | N15: 97.482274 | O15: 0 | P15: 2.5177258 | Q15: 0 | R15: =IF($A15=$A16,$C16-$C15,"") | S15: =IF(AND($A15=$A16,ISNUMBER(F15),ISNUMBER(F16)),(F16-F15)/($C16-$C15),"") | T15: =IF(AND($A15=$A16,ISNUMBER(J15),ISNUMBER(J16)),(J16-J15)/($C16-$C15),"") | U15: =IF(AND($A15=$A16,ISNUMBER(N15),ISNUMBER(N16)),(N16-N15)/($C16-$C15),"") | V15: =IF(ISNUMBER(F15),ROUND(F15,0),"") -> 97 | W15: =IF(ISNUMBER(J15),ROUND(J15,0),"") | X15: =IF(ISNUMBER(N15),ROUND(N15,0),"") -> 97 | Y15: =IF(AND($A15=$A16,V15=100,V16=100),"full access","") | Z15: =IF(AND($A15=$A16,W15=100,W16=100),"full access","") | AA15: =IF(AND($A15=$A16,X15=100,X16=100),"full access","") | AB15: =IF(AND(ISNUMBER(T15),ISNUMBER(U15)),T15-U15,"")
A16: Antigua and Barbuda | B16: =IFERROR(INDEX('Region Lookup'!$B$2:$B$233,MATCH(A16,'Region Lookup'!$A$2:$A$233,0)),"Not found") -> Latin America & Caribbean | C16: 2015 | D16: 93.570999 | E16: 25 | F16: 96.739186 | G16: 0 | H16: 3.1663476 | I16: 0.094466114 | R16: =IF($A16=$A17,$C17-$C16,"") -> 2 | S16: =IF(AND($A16=$A17,ISNUMBER(F16),ISNUMBER(F17)),(F17-F16)/($C17-$C16),"") -> 0 | T16: =IF(AND($A16=$A17,ISNUMBER(J16),ISNUMBER(J17)),(J17-J16)/($C17-$C16),"") | U16: =IF(AND($A16=$A17,ISNUMBER(N16),ISNUMBER(N17)),(N17-N16)/($C17-$C16),"") | V16: =IF(ISNUMBER(F16),ROUND(F16,0),"") -> 97 | W16: =IF(ISNUMBER(J16),ROUND(J16,0),"") | X16: =IF(ISNUMBER(N16),ROUND(N16,0),"") | Y16: =IF(AND($A16=$A17,V16=100,V17=100),"full access","") | Z16: =IF(AND($A16=$A17,W16=100,W17=100),"full access","") | AA16: =IF(AND($A16=$A17,X16=100,X17=100),"full access","") | AB16: =IF(AND(ISNUMBER(T16),ISNUMBER(U16)),T16-U16,"")
A17: Antigua and Barbuda | B17: =IFERROR(INDEX('Region Lookup'!$B$2:$B$233,MATCH(A17,'Region Lookup'!$A$2:$A$233,0)),"Not found") -> Latin America & Caribbean | C17: 2017 | D17: 95.425003 | E17: 24.713001 | F17: 96.739186 | G17: 0 | H17: 3.1663476 | I17: 0.094466114 | R17: =IF($A17=$A18,$C18-$C17,"") | S17: =IF(AND($A17=$A18,ISNUMBER(F17),ISNUMBER(F18)),(F18-F17)/($C18-$C17),"") | T17: =IF(AND($A17=$A18,ISNUMBER(J17),ISNUMBER(J18)),(J18-J17)/($C18-$C17),"") | U17: =IF(AND($A17=$A18,ISNUMBER(N17),ISNUMBER(N18)),(N18-N17)/($C18-$C17),"") | V17: =IF(ISNUMBER(F17),ROUND(F17,0),"") -> 97 | W17: =IF(ISNUMBER(J17),ROUND(J17,0),"") | X17: =IF(ISNUMBER(N17),ROUND(N17,0),"") | Y17: =IF(AND($A17=$A18,V17=100,V18=100),"full access","") | Z17: =IF(AND($A17=$A18,W17=100,W18=100),"full access","") | AA17: =IF(AND($A17=$A18,X17=100,X18=100),"full access","") | AB17: =IF(AND(ISNUMBER(T17),ISNUMBER(U17)),T17-U17,"")
A18: Argentina | B18: =IFERROR(INDEX('Region Lookup'!$B$2:$B$233,MATCH(A18,'Region Lookup'!$A$2:$A$233,0)),"Not found") -> Latin America & Caribbean | C18: 2015 | D18: 43075.414 | E18: 91.502998 | F18: 98.966588 | G18: 0 | H18: 0.66491438 | I18: 0.36849747 | J18: 92.98366 | K18: 0 | L18: 2.6795449 | M18: 4.3367951 | N18: 99.522163 | O18: 0 | P18: 0.47783695 | Q18: 0 | R18: =IF($A18=$A19,$C19-$C18,"") -> 5 | S18: =IF(AND($A18=$A19,ISNUMBER(F18),ISNUMBER(F19)),(F19-F18)/($C19-$C18),"") | T18: =IF(AND($A18=$A19,ISNUMBER(J18),ISNUMBER(J19)),(J19-J18)/($C19-$C18),"") | U18: =IF(AND($A18=$A19,ISNUMBER(N18),ISNUMBER(N19)),(N19-N18)/($C19-$C18),"") -> 0.05365152 | V18: =IF(ISNUMBER(F18),ROUND(F18,0),"") -> 99 | W18: =IF(ISNUMBER(J18),ROUND(J18,0),"") -> 93 | X18: =IF(ISNUMBER(N18),ROUND(N18,0),"") -> 100 | Y18: =IF(AND($A18=$A19,V18=100,V19=100),"full access","") | Z18: =IF(AND($A18=$A19,W18=100,W19=100),"full access","") | AA18: =IF(AND($A18=$A19,X18=100,X19=100),"full access","") -> full access | AB18: =IF(AND(ISNUMBER(T18),ISNUMBER(U18)),T18-U18,"")
A19: Argentina | B19: =IFERROR(INDEX('Region Lookup'!$B$2:$B$233,MATCH(A19,'Region Lookup'!$A$2:$A$233,0)),"Not found") -> Latin America & Caribbean | C19: 2020 | D19: 45195.777 | E19: 92.111 | N19: 99.790421 | O19: 0 | P19: 0.20957935 | Q19: 0 | R19: =IF($A19=$A20,$C20-$C19,"") | S19: =IF(AND($A19=$A20,ISNUMBER(F19),ISNUMBER(F20)),(F20-F19)/($C20-$C19),"") | T19: =IF(AND($A19=$A20,ISNUMBER(J19),ISNUMBER(J20)),(J20-J19)/($C20-$C19),"") | U19: =IF(AND($A19=$A20,ISNUMBER(N19),ISNUMBER(N20)),(N20-N19)/($C20-$C19),"") | V19: =IF(ISNUMBER(F19),ROUND(F19,0),"") | W19: =IF(ISNUMBER(J19),ROUND(J19,0),"") | X19: =IF(ISNUMBER(N19),ROUND(N19,0),"") -> 100 | Y19: =IF(AND($A19=$A20,V19=100,V20=100),"full access","") | Z19: =IF(AND($A19=$A20,W19=100,W20=100),"full access","") | AA19: =IF(AND($A19=$A20,X19=100,X20=100),"full access","") | AB19: =IF(AND(ISNUMBER(T19),ISNUMBER(U19)),T19-U19,"")
A20: Armenia | B20: =IFERROR(INDEX('Region Lookup'!$B$2:$B$233,MATCH(A20,'Region Lookup'!$A$2:$A$233,0)),"Not found") -> Europe & Central Asia | C20: 2015 | D20: 2925.5591 | E20: 63.085003 | F20: 99.552567 | G20: 0 | H20: 0.098505084 | I20: 0.34892822 | J20: 99.054779 | K20: 0 | L20: 0 | M20: 0.94522073 | N20: 99.843853 | O20: 0 | P20: 0.1561466 | Q20: 0 | R20: =IF($A20=$A21,$C21-$C20,"") -> 5 | S20: =IF(AND($A20=$A21,ISNUMBER(F20),ISNUMBER(F21)),(F21-F20)/($C21-$C20),"") -> 0.083722798 | T20: =IF(AND($A20=$A21,ISNUMBER(J20),ISNUMBER(J21)),(J21-J20)/($C21-$C20),"") -> 0.18904415 | U20: =IF(AND($A20=$A21,ISNUMBER(N20),ISNUMBER(N21)),(N21-N20)/($C21-$C20),"") -> 0.022125564 | V20: =IF(ISNUMBER(F20),ROUND(F20,0),"") -> 100 | W20: =IF(ISNUMBER(J20),ROUND(J20,0),"") -> 99 | X20: =IF(ISNUMBER(N20),ROUND(N20,0),"") -> 100 | Y20: =IF(AND($A20=$A21,V20=100,V21=100),"full access","") -> full access | Z20: =IF(AND($A20=$A21,W20=100,W21=100),"full access","") | AA20: =IF(AND($A20=$A21,X20=100,X21=100),"full access","") -> full access | AB20: =IF(AND(ISNUMBER(T20),ISNUMBER(U20)),T20-U20,"") -> 0.16691858
A21: Armenia | B21: =IFERROR(INDEX('Region Lookup'!$B$2:$B$233,MATCH(A21,'Region Lookup'!$A$2:$A$233,0)),"Not found") -> Europe & Central Asia | C21: 2020 | D21: 2963.2339 | E21: 63.313 | F21: 99.971181 | G21: 0 | H21: 0.028819308 | I21: 0 | J21: 100 | K21: 0 | L21: 0 | M21: 0 | N21: 99.954481 | O21: 0 | P21: 0.045518784 | Q21: 0 | R21: =IF($A21=$A22,$C22-$C21,"") | S21: =IF(AND($A21=$A22,ISNUMBER(F21),ISNUMBER(F22)),(F22-F21)/($C22-$C21),"") | T21: =IF(AND($A21=$A22,ISNUMBER(J21),ISNUMBER(J22)),(J22-J21)/($C22-$C21),"") | U21: =IF(AND($A21=$A22,ISNUMBER(N21),ISNUMBER(N22)),(N22-N21)/($C22-$C21),"") | V21: =IF(ISNUMBER(F21),ROUND(F21,0),"") -> 100 | W21: =IF(ISNUMBER(J21),ROUND(J21,0),"") -> 100 | X21: =IF(ISNUMBER(N21),ROUND(N21,0),"") -> 100 | Y21: =IF(AND($A21=$A22,V21=100,V22=100),"full access","") | Z21: =IF(AND($A21=$A22,W21=100,W22=100),"full access","") | AA21: =IF(AND($A21=$A22,X21=100,X22=100),"full access","") | AB21: =IF(AND(ISNUMBER(T21),ISNUMBER(U21)),T21-U21,"")
A22: Aruba | B22: =IFERROR(INDEX('Region Lookup'!$B$2:$B$233,MATCH(A22,'Region Lookup'!$A$2:$A$233,0)),"Not found") -> Latin America & Caribbean | C22: 2015 | D22: 104.339 | E22: 43.108002 | F22: 97.869023 | G22: 0 | H22: 1.9599362 | I22: 0.17104041 | R22: =IF($A22=$A23,$C23-$C22,"") -> 1 | S22: =IF(AND($A22=$A23,ISNUMBER(F22),ISNUMBER(F23)),(F23-F22)/($C23-$C22),"") -> 0 | T22: =IF(AND($A22=$A23,ISNUMBER(J22),ISNUMBER(J23)),(J23-J22)/($C23-$C22),"") | U22: =IF(AND($A22=$A23,ISNUMBER(N22),ISNUMBER(N23)),(N23-N22)/($C23-$C22),"") | V22: =IF(ISNUMBER(F22),ROUND(F22,0),"") -> 98 | W22: =IF(ISNUMBER(J22),ROUND(J22,0),"") | X22: =IF(ISNUMBER(N22),ROUND(N22,0),"") | Y22: =IF(AND($A22=$A23,V22=100,V23=100),"full access","") | Z22: =IF(AND($A22=$A23,W22=100,W23=100),"full access","") | AA22: =IF(AND($A22=$A23,X22=100,X23=100),"full access","") | AB22: =IF(AND(ISNUMBER(T22),ISNUMBER(U22)),T22-U22,"")
A23: Aruba | B23: =IFERROR(INDEX('Region Lookup'!$B$2:$B$233,MATCH(A23,'Region Lookup'!$A$2:$A$233,0)),"Not found") -> Latin America & Caribbean | C23: 2016 | D23: 104.865 | E23: 43.191998 | F23: 97.869023 | G23: 0 | H23: 1.9599362 | I23: 0.17104041 | R23: =IF($A23=$A24,$C24-$C23,"") | S23: =IF(AND($A23=$A24,ISNUMBER(F23),ISNUMBER(F24)),(F24-F23)/($C24-$C23),"") | T23: =IF(AND($A23=$A24,ISNUMBER(J23),ISNUMBER(J24)),(J24-J23)/($C24-$C23),"") | U23: =IF(AND($A23=$A24,ISNUMBER(N23),ISNUMBER(N24)),(N24-N23)/($C24-$C23),"") | V23: =IF(ISNUMBER(F23),ROUND(F23,0),"") -> 98 | W23: =IF(ISNUMBER(J23),ROUND(J23,0),"") | X23: =IF(ISNUMBER(N23),ROUND(N23,0),"") | Y23: =IF(AND($A23=$A24,V23=100,V24=100),"full access","") | Z23: =IF(AND($A23=$A24,W23=100,W24=100),"full access","") | AA23: =IF(AND($A23=$A24,X23=100,X24=100),"full access","") | AB23: =IF(AND(ISNUMBER(T23),ISNUMBER(U23)),T23-U23,"")
A24: Australia | B24: =IFERROR(INDEX('Region Lookup'!$B$2:$B$233,MATCH(A24,'Region Lookup'!$A$2:$A$233,0)),"Not found") -> East Asia & Pacific | C24: 2015 | D24: 23932.498 | E24: 85.701004 | F24: 99.970006 | G24: 0 | H24: 0.029994331 | I24: 0 | J24: 100 | K24: 0 | L24: 0 | M24: 0 | N24: 99.965 | O24: 0 | P24: 0.035 | Q24: 0 | R24: =IF($A24=$A25,$C25-$C24,"") -> 5 | S24: =IF(AND($A24=$A25,ISNUMBER(F24),ISNUMBER(F25)),(F25-F24)/($C25-$C24),"") -> -3.877e-05 | T24: =IF(AND($A24=$A25,ISNUMBER(J24),ISNUMBER(J25)),(J25-J24)/($C25-$C24),"") -> 0 | U24: =IF(AND($A24=$A25,ISNUMBER(N24),ISNUMBER(N25)),(N25-N24)/($C25-$C24),"") -> 0 | V24: =IF(ISNUMBER(F24),ROUND(F24,0),"") -> 100 | W24: =IF(ISNUMBER(J24),ROUND(J24,0),"") -> 100 | X24: =IF(ISNUMBER(N24),ROUND(N24,0),"") -> 100 | Y24: =IF(AND($A24=$A25,V24=100,V25=100),"full access","") -> full access | Z24: =IF(AND($A24=$A25,W24=100,W25=100),"full access","") -> full access | AA24: =IF(AND($A24=$A25,X24=100,X25=100),"full access","") -> full access | AB24: =IF(AND(ISNUMBER(T24),ISNUMBER(U24)),T24-U24,"") -> 0
A25: Australia | B25: =IFERROR(INDEX('Region Lookup'!$B$2:$B$233,MATCH(A25,'Region Lookup'!$A$2:$A$233,0)),"Not found") -> East Asia & Pacific | C25: 2020 | D25: 25499.881 | E25: 86.240997 | F25: 99.969812 | G25: 0 | H25: 0.030188179 | I25: 0 | J25: 100 | K25: 0 | L25: 0 | M25: 0 | N25: 99.965 | O25: 0 | P25: 0.035 | Q25: 0 | R25: =IF($A25=$A26,$C26-$C25,"") | S25: =IF(AND($A25=$A26,ISNUMBER(F25),ISNUMBER(F26)),(F26-F25)/($C26-$C25),"") | T25: =IF(AND($A25=$A26,ISNUMBER(J25),ISNUMBER(J26)),(J26-J25)/($C26-$C25),"") | U25: =IF(AND($A25=$A26,ISNUMBER(N25),ISNUMBER(N26)),(N26-N25)/($C26-$C25),"") | V25: =IF(ISNUMBER(F25),ROUND(F25,0),"") -> 100 | W25: =IF(ISNUMBER(J25),ROUND(J25,0),"") -> 100 | X25: =IF(ISNUMBER(N25),ROUND(N25,0),"") -> 100 | Y25: =IF(AND($A25=$A26,V25=100,V26=100),"full access","") | Z25: =IF(AND($A25=$A26,W25=100,W26=100),"full access","") | AA25: =IF(AND($A25=$A26,X25=100,X26=100),"full access","") | AB25: =IF(AND(ISNUMBER(T25),ISNUMBER(U25)),T25-U25,"")
A26: Austria | B26: =IFERROR(INDEX('Region Lookup'!$B$2:$B$233,MATCH(A26,'Region Lookup'!$A$2:$A$233,0)),"Not found") -> Europe & Central Asia | C26: 2015 | D26: 8678.667 | E26: 57.715 | F26: 100 | G26: 0 | H26: 0 | I26: 0 | J26: 100 | K26: 0 | L26: 0 | M26: 0 | N26: 100 | O26: 0 | P26: 0 | Q26: 0 | R26: =IF($A26=$A27,$C27-$C26,"") -> 5 | S26: =IF(AND($A26=$A27,ISNUMBER(F26),ISNUMBER(F27)),(F27-F26)/($C27-$C26),"") -> 0 | T26: =IF(AND($A26=$A27,ISNUMBER(J26),ISNUMBER(J27)),(J27-J26)/($C27-$C26),"") -> 0 | U26: =IF(AND($A26=$A27,ISNUMBER(N26),ISNUMBER(N27)),(N27-N26)/($C27-$C26),"") -> 0 | V26: =IF(ISNUMBER(F26),ROUND(F26,0),"") -> 100 | W26: =IF(ISNUMBER(J26),ROUND(J26,0),"") -> 100 | X26: =IF(ISNUMBER(N26),ROUND(N26,0),"") -> 100 | Y26: =IF(AND($A26=$A27,V26=100,V27=100),"full access","") -> full access | Z26: =IF(AND($A26=$A27,W26=100,W27=100),"full access","") -> full access | AA26: =IF(AND($A26=$A27,X26=100,X27=100),"full access","") -> full access | AB26: =IF(AND(ISNUMBER(T26),ISNUMBER(U26)),T26-U26,"") -> 0
A27: Austria | B27: =IFERROR(INDEX('Region Lookup'!$B$2:$B$233,MATCH(A27,'Region Lookup'!$A$2:$A$233,0)),"Not found") -> Europe & Central Asia | C27: 2020 | D27: 9006.4004 | E27: 58.748001 | F27: 100 | G27: 0 | H27: 0 | I27: 0 | J27: 100 | K27: 0 | L27: 0 | M27: 0 | N27: 100 | O27: 0 | P27: 0 | Q27: 0 | R27: =IF($A27=$A28,$C28-$C27,"") | S27: =IF(AND($A27=$A28,ISNUMBER(F27),ISNUMBER(F28)),(F28-F27)/($C28-$C27),"") | T27: =IF(AND($A27=$A28,ISNUMBER(J27),ISNUMBER(J28)),(J28-J27)/($C28-$C27),"") | U27: =IF(AND($A27=$A28,ISNUMBER(N27),ISNUMBER(N28)),(N28-N27)/($C28-$C27),"") | V27: =IF(ISNUMBER(F27),ROUND(F27,0),"") -> 100 | W27: =IF(ISNUMBER(J27),ROUND(J27,0),"") -> 100 | X27: =IF(ISNUMBER(N27),ROUND(N27,0),"") -> 100 | Y27: =IF(AND($A27=$A28,V27=100,V28=100),"full access","") | Z27: =IF(AND($A27=$A28,W27=100,W28=100),"full access","") | AA27: =IF(AND($A27=$A28,X27=100,X28=100),"full access","") | AB27: =IF(AND(ISNUMBER(T27),ISNUMBER(U27)),T27-U27,"")
A28: Azerbaijan | B28: =IFERROR(INDEX('Region Lookup'!$B$2:$B$233,MATCH(A28,'Region Lookup'!$A$2:$A$233,0)),"Not found") -> Europe & Central Asia | C28: 2015 | D28: 9622.7412 | E28: 54.714001 | F28: 92.420314 | G28: 1.0022424 | H28: 4.3650895 | I28: 2.2123541 | J28: 84.143213 | K28: 2.2131397 | L28: 8.988206 | M28: 4.655441 | N28: 99.271152 | O28: 0 | P28: 0.53860203 | Q28: 0.19024593 | R28: =IF($A28=$A29,$C29-$C28,"") -> 5 | S28: =IF(AND($A28=$A29,ISNUMBER(F28),ISNUMBER(F29)),(F29-F28)/($C29-$C28),"") -> 0.72461243 | T28: =IF(AND($A28=$A29,ISNUMBER(J28),ISNUMBER(J29)),(J29-J28)/($C29-$C28),"") -> 1.3565169 | U28: =IF(AND($A28=$A29,ISNUMBER(N28),ISNUMBER(N29)),(N29-N28)/($C29-$C28),"") -> 0.14576959 | V28: =IF(ISNUMBER(F28),ROUND(F28,0),"") -> 92 | W28: =IF(ISNUMBER(J28),ROUND(J28,0),"") -> 84 | X28: =IF(ISNUMBER(N28),ROUND(N28,0),"") -> 99 | Y28: =IF(AND($A28=$A29,V28=100,V29=100),"full access","") | Z28: =IF(AND($A28=$A29,W28=100,W29=100),"full access","") | AA28: =IF(AND($A28=$A29,X28=100,X29=100),"full access","") | AB28: =IF(AND(ISNUMBER(T28),ISNUMBER(U28)),T28-U28,"") -> 1.2107473
A29: Azerbaijan | B29: =IFERROR(INDEX('Region Lookup'!$B$2:$B$233,MATCH(A29,'Region Lookup'!$A$2:$A$233,0)),"Not found") -> Europe & Central Asia | C29: 2020 | D29: 10139.175 | E29: 56.397003 | F29: 96.043376 | G29: 1.0427812 | H29: 2.9138427 | I29: 0 | J29: 90.925798 | K29: 2.3915357 | L29: 6.6826664 | M29: 0 | N29: 100 | O29: 0 | P29: 0 | Q29: 0 | R29: =IF($A29=$A30,$C30-$C29,"") | S29: =IF(AND($A29=$A30,ISNUMBER(F29),ISNUMBER(F30)),(F30-F29)/($C30-$C29),"") | T29: =IF(AND($A29=$A30,ISNUMBER(J29),ISNUMBER(J30)),(J30-J29)/($C30-$C29),"") | U29: =IF(AND($A29=$A30,ISNUMBER(N29),ISNUMBER(N30)),(N30-N29)/($C30-$C29),"") | V29: =IF(ISNUMBER(F29),ROUND(F29,0),"") -> 96 | W29: =IF(ISNUMBER(J29),ROUND(J29,0),"") -> 91 | X29: =IF(ISNUMBER(N29),ROUND(N29,0),"") -> 100 | Y29: =IF(AND($A29=$A30,V29=100,V30=100),"full access","") | Z29: =IF(AND($A29=$A30,W29=100,W30=100),"full access","") | AA29: =IF(AND($A29=$A30,X29=100,X30=100),"full access","") | AB29: =IF(AND(ISNUMBER(T29),ISNUMBER(U29)),T29-U29,"")
A30: Bahamas | B30: =IFERROR(INDEX('Region Lookup'!$B$2:$B$233,MATCH(A30,'Region Lookup'!$A$2:$A$233,0)),"Not found") -> Latin America & Caribbean | C30: 2015 | D30: 374.20001 | E30: 82.745995 | F30: 98.886961 | G30: 0 | H30: 1.1130395 | I30: 0 | R30: =IF($A30=$A31,$C31-$C30,"") -> 4 | S30: =IF(AND($A30=$A31,ISNUMBER(F30),ISNUMBER(F31)),(F31-F30)/($C31-$C30),"") -> 0 | T30: =IF(AND($A30=$A31,ISNUMBER(J30),ISNUMBER(J31)),(J31-J30)/($C31-$C30),"") | U30: =IF(AND($A30=$A31,ISNUMBER(N30),ISNUMBER(N31)),(N31-N30)/($C31-$C30),"") | V30: =IF(ISNUMBER(F30),ROUND(F30,0),"") -> 99 | W30: =IF(ISNUMBER(J30),ROUND(J30,0),"") | X30: =IF(ISNUMBER(N30),ROUND(N30,0),"") | Y30: =IF(AND($A30=$A31,V30=100,V31=100),"full access","") | Z30: =IF(AND($A30=$A31,W30=100,W31=100),"full access","") | AA30: =IF(AND($A30=$A31,X30=100,X31=100),"full access","") | AB30: =IF(AND(ISNUMBER(T30),ISNUMBER(U30)),T30-U30,"")
A31: Bahamas | B31: =IFERROR(INDEX('Region Lookup'!$B$2:$B$233,MATCH(A31,'Region Lookup'!$A$2:$A$233,0)),"Not found") -> Latin America & Caribbean | C31: 2019 | D31: 389.48599 | E31: 83.131996 | F31: 98.886961 | G31: 0 | H31: 1.1130395 | I31: 0 | R31: =IF($A31=$A32,$C32-$C31,"") | S31: =IF(AND($A31=$A32,ISNUMBER(F31),ISNUMBER(F32)),(F32-F31)/($C32-$C31),"") | T31: =IF(AND($A31=$A32,ISNUMBER(J31),ISNUMBER(J32)),(J32-J31)/($C32-$C31),"") | U31: =IF(AND($A31=$A32,ISNUMBER(N31),ISNUMBER(N32)),(N32-N31)/($C32-$C31),"") | V31: =IF(ISNUMBER(F31),ROUND(F31,0),"") -> 99 | W31: =IF(ISNUMBER(J31),ROUND(J31,0),"") | X31: =IF(ISNUMBER(N31),ROUND(N31,0),"") | Y31: =IF(AND($A31=$A32,V31=100,V32=100),"full access","") | Z31: =IF(AND($A31=$A32,W31=100,W32=100),"full access","") | AA31: =IF(AND($A31=$A32,X31=100,X32=100),"full access","") | AB31: =IF(AND(ISNUMBER(T31),ISNUMBER(U31)),T31-U31,"")
A32: Bahrain | B32: =IFERROR(INDEX('Region Lookup'!$B$2:$B$233,MATCH(A32,'Region Lookup'!$A$2:$A$233,0)),"Not found") -> Europe & Central Asia | C32: 2015 | D32: 1371.853 | E32: 88.998993 | F32: 100 | G32: 0 | H32: 0 | I32: 0 | R32: =IF($A32=$A33,$C33-$C32,"") -> 5 | S32: =IF(AND($A32=$A33,ISNUMBER(F32),ISNUMBER(F33)),(F33-F32)/($C33-$C32),"") -> 0 | T32: =IF(AND($A32=$A33,ISNUMBER(J32),ISNUMBER(J33)),(J33-J32)/($C33-$C32),"") | U32: =IF(AND($A32=$A33,ISNUMBER(N32),ISNUMBER(N33)),(N33-N32)/($C33-$C32),"") | V32: =IF(ISNUMBER(F32),ROUND(F32,0),"") -> 100 | W32: =IF(ISNUMBER(J32),ROUND(J32,0),"") | X32: =IF(ISNUMBER(N32),ROUND(N32,0),"") | Y32: =IF(AND($A32=$A33,V32=100,V33=100),"full access","") -> full access | Z32: =IF(AND($A32=$A33,W32=100,W33=100),"full access","") | AA32: =IF(AND($A32=$A33,X32=100,X33=100),"full access","") | AB32: =IF(AND(ISNUMBER(T32),ISNUMBER(U32)),T32-U32,"")
A33: Bahrain | B33: =IFERROR(INDEX('Region Lookup'!$B$2:$B$233,MATCH(A33,'Region Lookup'!$A$2:$A$233,0)),"Not found") -> Europe & Central Asia | C33: 2020 | D33: 1701.583 | E33: 89.506004 | F33: 100 | G33: 0 | H33: 0 | I33: 0 | R33: =IF($A33=$A34,$C34-$C33,"") | S33: =IF(AND($A33=$A34,ISNUMBER(F33),ISNUMBER(F34)),(F34-F33)/($C34-$C33),"") | T33: =IF(AND($A33=$A34,ISNUMBER(J33),ISNUMBER(J34)),(J34-J33)/($C34-$C33),"") | U33: =IF(AND($A33=$A34,ISNUMBER(N33),ISNUMBER(N34)),(N34-N33)/($C34-$C33),"") | V33: =IF(ISNUMBER(F33),ROUND(F33,0),"") -> 100 | W33: =IF(ISNUMBER(J33),ROUND(J33,0),"") | X33: =IF(ISNUMBER(N33),ROUND(N33,0),"") | Y33: =IF(AND($A33=$A34,V33=100,V34=100),"full access","") | Z33: =IF(AND($A33=$A34,W33=100,W34=100),"full access","") | AA33: =IF(AND($A33=$A34,X33=100,X34=100),"full access","") | AB33: =IF(AND(ISNUMBER(T33),ISNUMBER(U33)),T33-U33,"")
A34: Bangladesh | B34: =IFERROR(INDEX('Region Lookup'!$B$2:$B$233,MATCH(A34,'Region Lookup'!$A$2:$A$233,0)),"Not found") -> South Asia | C34: 2015 | D34: 156256.28 | E34: 34.308002 | F34: 97.101602 | G34: 1.087989 | H34: 0.72156166 | I34: 1.0888469 | J34: 96.773011 | K34: 1.0462142 | L34: 0.73174732 | M34: 1.4490272 | N34: 97.73078 | O34: 1.1679782 | P34: 0.70205843 | Q34: 0.39918371 | R34: =IF($A34=$A35,$C35-$C34,"") -> 5 | S34: =IF(AND($A34=$A35,ISNUMBER(F34),ISNUMBER(F35)),(F35-F34)/($C35-$C34),"") -> 0.11927156 | T34: =IF(AND($A34=$A35,ISNUMBER(J34),ISNUMBER(J35)),(J35-J34)/($C35-$C34),"") -> 0.2214453 | U34: =IF(AND($A34=$A35,ISNUMBER(N34),ISNUMBER(N35)),(N35-N34)/($C35-$C34),"") -> -0.065600342 | V34: =IF(ISNUMBER(F34),ROUND(F34,0),"") -> 97 | W34: =IF(ISNUMBER(J34),ROUND(J34,0),"") -> 97 | X34: =IF(ISNUMBER(N34),ROUND(N34,0),"") -> 98 | Y34: =IF(AND($A34=$A35,V34=100,V35=100),"full access","") | Z34: =IF(AND($A34=$A35,W34=100,W35=100),"full access","") | AA34: =IF(AND($A34=$A35,X34=100,X35=100),"full access","") | AB34: =IF(AND(ISNUMBER(T34),ISNUMBER(U34)),T34-U34,"") -> 0.28704564
A35: Bangladesh | B35: =IFERROR(INDEX('Region Lookup'!$B$2:$B$233,MATCH(A35,'Region Lookup'!$A$2:$A$233,0)),"Not found") -> South Asia | C35: 2020 | D35: 164689.39 | E35: 38.177002 | F35: 97.69796 | G35: 1.1564259 | H35: 0.4626557 | I35: 0.68295817 | J35: 97.880238 | K35: 0.85810498 | L35: 0.31648024 | M35: 0.94517702 | N35: 97.402778 | O35: 1.6395201 | P35: 0.69937521 | Q35: 0.25832669 | R35: =IF($A35=$A36,$C36-$C35,"") | S35: =IF(AND($A35=$A36,ISNUMBER(F35),ISNUMBER(F36)),(F36-F35)/($C36-$C35),"") | T35: =IF(AND($A35=$A36,ISNUMBER(J35),ISNUMBER(J36)),(J36-J35)/($C36-$C35),"") | U35: =IF(AND($A35=$A36,ISNUMBER(N35),ISNUMBER(N36)),(N36-N35)/($C36-$C35),"") | V35: =IF(ISNUMBER(F35),ROUND(F35,0),"") -> 98 | W35: =IF(ISNUMBER(J35),ROUND(J35,0),"") -> 98 | X35: =IF(ISNUMBER(N35),ROUND(N35,0),"") -> 97 | Y35: =IF(AND($A35=$A36,V35=100,V36=100),"full access","") | Z35: =IF(AND($A35=$A36,W35=100,W36=100),"full access","") | AA35: =IF(AND($A35=$A36,X35=100,X36=100),"full access","") | AB35: =IF(AND(ISNUMBER(T35),ISNUMBER(U35)),T35-U35,"")
A36: Barbados | B36: =IFERROR(INDEX('Region Lookup'!$B$2:$B$233,MATCH(A36,'Region Lookup'!$A$2:$A$233,0)),"Not found") -> Latin America & Caribbean | C36: 2015 | D36: 285.327 | E36: 31.248999 | F36: 98.474445 | G36: 0.26749191 | H36: 1.2580634 | I36: 0 | R36: =IF($A36=$A37,$C37-$C36,"") -> 5 | S36: =IF(AND($A36=$A37,ISNUMBER(F36),ISNUMBER(F37)),(F37-F36)/($C37-$C36),"") -> 0.008001136 | T36: =IF(AND($A36=$A37,ISNUMBER(J36),ISNUMBER(J37)),(J37-J36)/($C37-$C36),"") | U36: =IF(AND($A36=$A37,ISNUMBER(N36),ISNUMBER(N37)),(N37-N36)/($C37-$C36),"") | V36: =IF(ISNUMBER(F36),ROUND(F36,0),"") -> 98 | W36: =IF(ISNUMBER(J36),ROUND(J36,0),"") | X36: =IF(ISNUMBER(N36),ROUND(N36,0),"") | Y36: =IF(AND($A36=$A37,V36=100,V37=100),"full access","") | Z36: =IF(AND($A36=$A37,W36=100,W37=100),"full access","") | AA36: =IF(AND($A36=$A37,X36=100,X37=100),"full access","") | AB36: =IF(AND(ISNUMBER(T36),ISNUMBER(U36)),T36-U36,"")
A37: Barbados | B37: =IFERROR(INDEX('Region Lookup'!$B$2:$B$233,MATCH(A37,'Region Lookup'!$A$2:$A$233,0)),"Not found") -> Latin America & Caribbean | C37: 2020 | D37: 287.371 | E37: 31.191 | F37: 98.51445 | G37: 0.26760058 | H37: 1.217949 | I37: 0 | R37: =IF($A37=$A38,$C38-$C37,"") | S37: =IF(AND($A37=$A38,ISNUMBER(F37),ISNUMBER(F38)),(F38-F37)/($C38-$C37),"") | T37: =IF(AND($A37=$A38,ISNUMBER(J37),ISNUMBER(J38)),(J38-J37)/($C38-$C37),"") | U37: =IF(AND($A37=$A38,ISNUMBER(N37),ISNUMBER(N38)),(N38-N37)/($C38-$C37),"") | V37: =IF(ISNUMBER(F37),ROUND(F37,0),"") -> 99 | W37: =IF(ISNUMBER(J37),ROUND(J37,0),"") | X37: =IF(ISNUMBER(N37),ROUND(N37,0),"") | Y37: =IF(AND($A37=$A38,V37=100,V38=100),"full access","") | Z37: =IF(AND($A37=$A38,W37=100,W38=100),"full access","") | AA37: =IF(AND($A37=$A38,X37=100,X38=100),"full access","") | AB37: =IF(AND(ISNUMBER(T37),ISNUMBER(U37)),T37-U37,"")
A38: Belarus | B38: =IFERROR(INDEX('Region Lookup'!$B$2:$B$233,MATCH(A38,'Region Lookup'!$A$2:$A$233,0)),"Not found") -> Europe & Central Asia | C38: 2015 | D38: 9439.4238 | E38: 77.181 | F38: 96.477067 | G38: 3.3001301 | H38: 0.2228028 | I38: 0 | J38: 98.330672 | K38: 0.99323911 | L38: 0.67608929 | M38: 0 | N38: 95.929035 | O38: 3.9821754 | P38: 0.088789424 | Q38: 0 | R38: =IF($A38=$A39,$C39-$C38,"") -> 5 | S38: =IF(AND($A38=$A39,ISNUMBER(F38),ISNUMBER(F39)),(F39-F38)/($C39-$C38),"") -> 0.011531798 | T38: =IF(AND($A38=$A39,ISNUMBER(J38),ISNUMBER(J39)),(J39-J38)/($C39-$C38),"") -> 0.046690142 | U38: =IF(AND($A38=$A39,ISNUMBER(N38),ISNUMBER(N39)),(N39-N38)/($C39-$C38),"") -> 0.016367688 | V38: =IF(ISNUMBER(F38),ROUND(F38,0),"") -> 96 | W38: =IF(ISNUMBER(J38),ROUND(J38,0),"") -> 98 | X38: =IF(ISNUMBER(N38),ROUND(N38,0),"") -> 96 | Y38: =IF(AND($A38=$A39,V38=100,V39=100),"full access","") | Z38: =IF(AND($A38=$A39,W38=100,W39=100),"full access","") | AA38: =IF(AND($A38=$A39,X38=100,X39=100),"full access","") | AB38: =IF(AND(ISNUMBER(T38),ISNUMBER(U38)),T38-U38,"") -> 0.030322454
A39: Belarus | B39: =IFERROR(INDEX('Region Lookup'!$B$2:$B$233,MATCH(A39,'Region Lookup'!$A$2:$A$233,0)),"Not found") -> Europe & Central Asia | C39: 2020 | D39: 9449.3213 | E39: 79.483002 | F39: 96.534726 | G39: 3.3721195 | H39: 0.093154368 | I39: 0 | J39: 98.564122 | K39: 0.9955972 | L39: 0.44028049 | M39: 0 | N39: 96.010874 | O39: 3.9855726 | P39: 0.003553732 | Q39: 0 | R39: =IF($A39=$A40,$C40-$C39,"") | S39: =IF(AND($A39=$A40,ISNUMBER(F39),ISNUMBER(F40)),(F40-F39)/($C40-$C39),"") | T39: =IF(AND($A39=$A40,ISNUMBER(J39),ISNUMBER(J40)),(J40-J39)/($C40-$C39),"") | U39: =IF(AND($A39=$A40,ISNUMBER(N39),ISNUMBER(N40)),(N40-N39)/($C40-$C39),"") | V39: =IF(ISNUMBER(F39),ROUND(F39,0),"") -> 97 | W39: =IF(ISNUMBER(J39),ROUND(J39,0),"") -> 99 | X39: =IF(ISNUMBER(N39),ROUND(N39,0),"") -> 96 | Y39: =IF(AND($A39=$A40,V39=100,V40=100),"full access","") | Z39: =IF(AND($A39=$A40,W39=100,W40=100),"full access","") | AA39: =IF(AND($A39=$A40,X39=100,X40=100),"full access","") | AB39: =IF(AND(ISNUMBER(T39),ISNUMBER(U39)),T39-U39,"")
A40: Belgium | B40: =IFERROR(INDEX('Region Lookup'!$B$2:$B$233,MATCH(A40,'Region Lookup'!$A$2:$A$233,0)),"Not found") -> Europe & Central Asia | C40: 2015 | D40: 11287.931 | E40: 97.875999 | F40: 99.999998 | G40: 0 | H40: 2.2980245e-06 | I40: 0 | J40: 100 | K40: 0 | L40: 0 | M40: 0 | N40: 100 | O40: 0 | P40: 0 | Q40: 0 | R40: =IF($A40=$A41,$C41-$C40,"") -> 5 | S40: =IF(AND($A40=$A41,ISNUMBER(F40),ISNUMBER(F41)),(F41-F40)/($C41-$C40),"") -> -2.5e-07 | T40: =IF(AND($A40=$A41,ISNUMBER(J40),ISNUMBER(J41)),(J41-J40)/($C41-$C40),"") -> 0 | U40: =IF(AND($A40=$A41,ISNUMBER(N40),ISNUMBER(N41)),(N41-N40)/($C41-$C40),"") -> 0 | V40: =IF(ISNUMBER(F40),ROUND(F40,0),"") -> 100 | W40: =IF(ISNUMBER(J40),ROUND(J40,0),"") -> 100 | X40: =IF(ISNUMBER(N40),ROUND(N40,0),"") -> 100 | Y40: =IF(AND($A40=$A41,V40=100,V41=100),"full access","") -> full access | Z40: =IF(AND($A40=$A41,W40=100,W41=100),"full access","") -> full access | AA40: =IF(AND($A40=$A41,X40=100,X41=100),"full access","") -> full access | AB40: =IF(AND(ISNUMBER(T40),ISNUMBER(U40)),T40-U40,"") -> 0
...

Sheet Summary
A1: Global 2000–2020 Report
A2: Annual Rate of Change (ARC) = yearly change in access to basic water, in percentage points.
A4: 1. Years covered | D4: Year | E4: Records
A5: Countries | B5: =COUNT(Data!$R$2:$R$463) -> 231 | D5: 2015 | E5: =COUNTIF(Data!$C$2:$C$463,2015) -> 231
A6: First year | B6: =MIN(Data!$C$2:$C$463) -> 2015 | D6: 2016 | E6: =COUNTIF(Data!$C$2:$C$463,2016) -> 3
A7: Last year | B7: =MAX(Data!$C$2:$C$463) -> 2020 | D7: 2017 | E7: =COUNTIF(Data!$C$2:$C$463,2017) -> 9
A8: Average gap between records (years) | B8: =ROUND(AVERAGE(Data!$R$2:$R$463),2) -> 4.8 | D8: 2018 | E8: =COUNTIF(Data!$C$2:$C$463,2018) -> 2
A9: Median gap (years) | B9: =MEDIAN(Data!$R$2:$R$463) -> 5 | D9: 2019 | E9: =COUNTIF(Data!$C$2:$C$463,2019) -> 4
A10: Shortest gap (years) | B10: =MIN(Data!$R$2:$R$463) -> 1 | D10: 2020 | E10: =COUNTIF(Data!$C$2:$C$463,2020) -> 213
A11: Longest gap (years) | B11: =MAX(Data!$R$2:$R$463) -> 5
A18: 2. Annual Rates of Change (percentage points per year)
A19: Area | B19: Countries with ARC | C19: No ARC value | D19: Mean | E19: Median | F19: Min | G19: Max
A20: National | B20: =COUNT(Data!$S$2:$S$463) -> 229 | C20: =SUMPRODUCT(ISNUMBER(Data!$R$2:$R$463)*NOT(ISNUMBER(Data!$S$2:$S$463))) -> 2 | D20: =AVERAGE(Data!$S$2:$S$463) -> 0.27699608 | E20: =MEDIAN(Data!$S$2:$S$463) -> 0.07858998 | F20: =MIN(Data!$S$2:$S$463) -> -1.0217887 | G20: =MAX(Data!$S$2:$S$463) -> 2.7503265
A21: Rural | B21: =COUNT(Data!$T$2:$T$463) -> 167 | C21: =SUMPRODUCT(ISNUMBER(Data!$R$2:$R$463)*NOT(ISNUMBER(Data!$T$2:$T$463))) -> 64 | D21: =AVERAGE(Data!$T$2:$T$463) -> 0.48445493 | E21: =MEDIAN(Data!$T$2:$T$463) -> 0.2897808 | F21: =MIN(Data!$T$2:$T$463) -> -1.227381 | G21: =MAX(Data!$T$2:$T$463) -> 2.6678826
A22: Urban | B22: =COUNT(Data!$U$2:$U$463) -> 181 | C22: =SUMPRODUCT(ISNUMBER(Data!$R$2:$R$463)*NOT(ISNUMBER(Data!$U$2:$U$463))) -> 50 | D22: =AVERAGE(Data!$U$2:$U$463) -> 0.15446264 | E22: =MEDIAN(Data!$U$2:$U$463) -> 0.03014517 | F22: =MIN(Data!$U$2:$U$463) -> -1.6200868 | G22: =MAX(Data!$U$2:$U$463) -> 2.6682119
A25: 3. Change in access by area (number of countries)
A26: Area | B26: No ARC value | C26: Full access (both years) | D26: No change (ARC = 0) | E26: Decrease (ARC < 0) | F26: Increase (ARC > 0) | G26: Total | H26: Check
A27: National | B27: =C20 -> 2 | C27: =COUNTIF(Data!$Y$2:$Y$463,"full access") -> 62 | D27: =COUNTIFS(Data!$S$2:$S$463,0,Data!$Y$2:$Y$463,"<>full access") -> 16 | E27: =COUNTIFS(Data!$S$2:$S$463,"<0",Data!$Y$2:$Y$463,"<>full access") -> 16 | F27: =COUNTIFS(Data!$S$2:$S$463,">0",Data!$Y$2:$Y$463,"<>full access") -> 135 | G27: =SUM(B27:F27) -> 231 | H27: =IF(G27=$B$5,"OK","Mismatch") -> OK
A28: Rural | B28: =C21 -> 64 | C28: =COUNTIF(Data!$Z$2:$Z$463,"full access") -> 29 | D28: =COUNTIFS(Data!$T$2:$T$463,0,Data!$Z$2:$Z$463,"<>full access") -> 5 | E28: =COUNTIFS(Data!$T$2:$T$463,"<0",Data!$Z$2:$Z$463,"<>full access") -> 17 | F28: =COUNTIFS(Data!$T$2:$T$463,">0",Data!$Z$2:$Z$463,"<>full access") -> 116 | G28: =SUM(B28:F28) -> 231 | H28: =IF(G28=$B$5,"OK","Mismatch") -> OK
A29: Urban | B29: =C22 -> 50 | C29: =COUNTIF(Data!$AA$2:$AA$463,"full access") -> 55 | D29: =COUNTIFS(Data!$U$2:$U$463,0,Data!$AA$2:$AA$463,"<>full access") -> 7 | E29: =COUNTIFS(Data!$U$2:$U$463,"<0",Data!$AA$2:$AA$463,"<>full access") -> 26 | F29: =COUNTIFS(Data!$U$2:$U$463,">0",Data!$AA$2:$AA$463,"<>full access") -> 93 | G29: =SUM(B29:F29) -> 231 | H29: =IF(G29=$B$5,"OK","Mismatch") -> OK
A32: 4. Rural vs urban ARC difference (rural − urban, points per year)
A33: Measure | B33: Value | C33: Country | E33: From | F33: To | G33: Countries
A34: Countries with both ARCs | B34: =COUNT(Data!$AB$2:$AB$463) -> 165 | E34: -3 | F34: -2.5 | G34: =COUNTIFS(Data!$AB$2:$AB$463,">="&E34,Data!$AB$2:$AB$463,"<"&F34) -> 0 | H34: =TEXT(E34,"0.0")&" to "&TEXT(F34,"0.0") -> -3.0 to -2.5
A35: Mean difference | B35: =AVERAGE(Data!$AB$2:$AB$463) -> 0.32116586 | E35: -2.5 | F35: -2 | G35: =COUNTIFS(Data!$AB$2:$AB$463,">="&E35,Data!$AB$2:$AB$463,"<"&F35) -> 1 | H35: =TEXT(E35,"0.0")&" to "&TEXT(F35,"0.0") -> -2.5 to -2.0
A36: Countries where rural improved faster | B36: =COUNTIF(Data!$AB$2:$AB$463,">0") -> 112 | E36: -2 | F36: -1.5 | G36: =COUNTIFS(Data!$AB$2:$AB$463,">="&E36,Data!$AB$2:$AB$463,"<"&F36) -> 0 | H36: =TEXT(E36,"0.0")&" to "&TEXT(F36,"0.0") -> -2.0 to -1.5
A37: Countries where urban improved faster | B37: =COUNTIF(Data!$AB$2:$AB$463,"<0") -> 23 | E37: -1.5 | F37: -1 | G37: =COUNTIFS(Data!$AB$2:$AB$463,">="&E37,Data!$AB$2:$AB$463,"<"&F37) -> 1 | H37: =TEXT(E37,"0.0")&" to "&TEXT(F37,"0.0") -> -1.5 to -1.0
A38: Largest gap in favour of rural | B38: =MAX(Data!$AB$2:$AB$463) -> 2.3292538 | C38: =INDEX(Data!$A$2:$A$463,MATCH(B38,Data!$AB$2:$AB$463,0)) -> Morocco | E38: -1 | F38: -0.5 | G38: =COUNTIFS(Data!$AB$2:$AB$463,">="&E38,Data!$AB$2:$AB$463,"<"&F38) -> 3 | H38: =TEXT(E38,"0.0")&" to "&TEXT(F38,"0.0") -> -1.0 to -0.5
A39: Largest gap in favour of urban | B39: =MIN(Data!$AB$2:$AB$463) -> -2.4887956 | C39: =INDEX(Data!$A$2:$A$463,MATCH(B39,Data!$AB$2:$AB$463,0)) -> South Sudan | E39: -0.5 | F39: 0 | G39: =COUNTIFS(Data!$AB$2:$AB$463,">="&E39,Data!$AB$2:$AB$463,"<"&F39) -> 18 | H39: =TEXT(E39,"0.0")&" to "&TEXT(F39,"0.0") -> -0.5 to 0.0
E40: 0 | F40: 0.5 | G40: =COUNTIFS(Data!$AB$2:$AB$463,">="&E40,Data!$AB$2:$AB$463,"<"&F40) -> 89 | H40: =TEXT(E40,"0.0")&" to "&TEXT(F40,"0.0") -> 0.0 to 0.5
E41: 0.5 | F41: 1 | G41: =COUNTIFS(Data!$AB$2:$AB$463,">="&E41,Data!$AB$2:$AB$463,"<"&F41) -> 35 | H41: =TEXT(E41,"0.0")&" to "&TEXT(F41,"0.0") -> 0.5 to 1.0
E42: 1 | F42: 1.5 | G42: =COUNTIFS(Data!$AB$2:$AB$463,">="&E42,Data!$AB$2:$AB$463,"<"&F42) -> 14 | H42: =TEXT(E42,"0.0")&" to "&TEXT(F42,"0.0") -> 1.0 to 1.5
E43: 1.5 | F43: 2 | G43: =COUNTIFS(Data!$AB$2:$AB$463,">="&E43,Data!$AB$2:$AB$463,"<"&F43) -> 3 | H43: =TEXT(E43,"0.0")&" to "&TEXT(F43,"0.0") -> 1.5 to 2.0
E44: 2 | F44: 2.5 | G44: =COUNTIFS(Data!$AB$2:$AB$463,">="&E44,Data!$AB$2:$AB$463,"<"&F44) -> 1 | H44: =TEXT(E44,"0.0")&" to "&TEXT(F44,"0.0") -> 2.0 to 2.5
E45: 2.5 | F45: 3 | G45: =COUNTIFS(Data!$AB$2:$AB$463,">="&E45,Data!$AB$2:$AB$463,"<"&F45) -> 0 | H45: =TEXT(E45,"0.0")&" to "&TEXT(F45,"0.0") -> 2.5 to 3.0

Sheet Regions
A1: Access to Water by Region – 2000–2020
A2: Average Annual Rates of Change per region (points per year). Population = latest year, in millions.
A4: Region | B4: Countries | C4: Population (millions) | D4: Avg ARC – national | E4: Avg ARC – rural | F4: Avg ARC – urban | G4: Full access – national | H4: Full access – rural | I4: Full access – urban
A5: East Asia & Pacific | B5: =COUNTIFS(Data!$B$2:$B$463,A5,Data!$R$2:$R$463,">=0") -> 40 | C5: =SUMPRODUCT((Data!$B$2:$B$463=A5)*NOT(ISNUMBER(Data!$R$2:$R$463))*Data!$D$2:$D$463)/1000 -> 2247.5367 | D5: =IFERROR(AVERAGEIF(Data!$B$2:$B$463,A5,Data!$S$2:$S$463),"") -> 0.2784349 | E5: =IFERROR(AVERAGEIF(Data!$B$2:$B$463,A5,Data!$T$2:$T$463),"") -> 0.5077948 | F5: =IFERROR(AVERAGEIF(Data!$B$2:$B$463,A5,Data!$U$2:$U$463),"") -> 0.23295792 | G5: =COUNTIFS(Data!$B$2:$B$463,A5,Data!$Y$2:$Y$463,"full access") -> 14 | H5: =COUNTIFS(Data!$B$2:$B$463,A5,Data!$Z$2:$Z$463,"full access") -> 4 | I5: =COUNTIFS(Data!$B$2:$B$463,A5,Data!$AA$2:$AA$463,"full access") -> 10
A6: Europe & Central Asia | B6: =COUNTIFS(Data!$B$2:$B$463,A6,Data!$R$2:$R$463,">=0") -> 64 | C6: =SUMPRODUCT((Data!$B$2:$B$463=A6)*NOT(ISNUMBER(Data!$R$2:$R$463))*Data!$D$2:$D$463)/1000 -> 1017.4768 | D6: =IFERROR(AVERAGEIF(Data!$B$2:$B$463,A6,Data!$S$2:$S$463),"") -> 0.11168578 | E6: =IFERROR(AVERAGEIF(Data!$B$2:$B$463,A6,Data!$T$2:$T$463),"") -> 0.22440971 | F6: =IFERROR(AVERAGEIF(Data!$B$2:$B$463,A6,Data!$U$2:$U$463),"") -> 0.046995216 | G6: =COUNTIFS(Data!$B$2:$B$463,A6,Data!$Y$2:$Y$463,"full access") -> 37 | H6: =COUNTIFS(Data!$B$2:$B$463,A6,Data!$Z$2:$Z$463,"full access") -> 23 | I6: =COUNTIFS(Data!$B$2:$B$463,A6,Data!$AA$2:$AA$463,"full access") -> 31
A7: Latin America & Caribbean | B7: =COUNTIFS(Data!$B$2:$B$463,A7,Data!$R$2:$R$463,">=0") -> 48 | C7: =SUMPRODUCT((Data!$B$2:$B$463=A7)*NOT(ISNUMBER(Data!$R$2:$R$463))*Data!$D$2:$D$463)/1000 -> 642.51317 | D7: =IFERROR(AVERAGEIF(Data!$B$2:$B$463,A7,Data!$S$2:$S$463),"") -> 0.14442485 | E7: =IFERROR(AVERAGEIF(Data!$B$2:$B$463,A7,Data!$T$2:$T$463),"") -> 0.6803145 | F7: =IFERROR(AVERAGEIF(Data!$B$2:$B$463,A7,Data!$U$2:$U$463),"") -> 0.071521594 | G7: =COUNTIFS(Data!$B$2:$B$463,A7,Data!$Y$2:$Y$463,"full access") -> 6 | H7: =COUNTIFS(Data!$B$2:$B$463,A7,Data!$Z$2:$Z$463,"full access") -> 0 | I7: =COUNTIFS(Data!$B$2:$B$463,A7,Data!$AA$2:$AA$463,"full access") -> 9
A8: Middle East & North Africa | B8: =COUNTIFS(Data!$B$2:$B$463,A8,Data!$R$2:$R$463,">=0") -> 10 | C8: =SUMPRODUCT((Data!$B$2:$B$463=A8)*NOT(ISNUMBER(Data!$R$2:$R$463))*Data!$D$2:$D$463)/1000 -> 311.0742 | D8: =IFERROR(AVERAGEIF(Data!$B$2:$B$463,A8,Data!$S$2:$S$463),"") -> 0.34556302 | E8: =IFERROR(AVERAGEIF(Data!$B$2:$B$463,A8,Data!$T$2:$T$463),"") -> 0.73698723 | F8: =IFERROR(AVERAGEIF(Data!$B$2:$B$463,A8,Data!$U$2:$U$463),"") -> 0.12397804 | G8: =COUNTIFS(Data!$B$2:$B$463,A8,Data!$Y$2:$Y$463,"full access") -> 1 | H8: =COUNTIFS(Data!$B$2:$B$463,A8,Data!$Z$2:$Z$463,"full access") -> 0 | I8: =COUNTIFS(Data!$B$2:$B$463,A8,Data!$AA$2:$AA$463,"full access") -> 1
A9: North America | B9: =COUNTIFS(Data!$B$2:$B$463,A9,Data!$R$2:$R$463,">=0") -> 5 | C9: =SUMPRODUCT((Data!$B$2:$B$463=A9)*NOT(ISNUMBER(Data!$R$2:$R$463))*Data!$D$2:$D$463)/1000 -> 368.86965 | D9: =IFERROR(AVERAGEIF(Data!$B$2:$B$463,A9,Data!$S$2:$S$463),"") -> 0.017158396 | E9: =IFERROR(AVERAGEIF(Data!$B$2:$B$463,A9,Data!$T$2:$T$463),"") -> 0.14233131 | F9: =IFERROR(AVERAGEIF(Data!$B$2:$B$463,A9,Data!$U$2:$U$463),"") -> 0.0020331735 | G9: =COUNTIFS(Data!$B$2:$B$463,A9,Data!$Y$2:$Y$463,"full access") -> 2 | H9: =COUNTIFS(Data!$B$2:$B$463,A9,Data!$Z$2:$Z$463,"full access") -> 1 | I9: =COUNTIFS(Data!$B$2:$B$463,A9,Data!$AA$2:$AA$463,"full access") -> 3
A10: South Asia | B10: =COUNTIFS(Data!$B$2:$B$463,A10,Data!$R$2:$R$463,">=0") -> 11 | C10: =SUMPRODUCT((Data!$B$2:$B$463=A10)*NOT(ISNUMBER(Data!$R$2:$R$463))*Data!$D$2:$D$463)/1000 -> 2082.3167 | D10: =IFERROR(AVERAGEIF(Data!$B$2:$B$463,A10,Data!$S$2:$S$463),"") -> 0.4802304 | E10: =IFERROR(AVERAGEIF(Data!$B$2:$B$463,A10,Data!$T$2:$T$463),"") -> 0.55914463 | F10: =IFERROR(AVERAGEIF(Data!$B$2:$B$463,A10,Data!$U$2:$U$463),"") -> 0.26548867 | G10: =COUNTIFS(Data!$B$2:$B$463,A10,Data!$Y$2:$Y$463,"full access") -> 0 | H10: =COUNTIFS(Data!$B$2:$B$463,A10,Data!$Z$2:$Z$463,"full access") -> 0 | I10: =COUNTIFS(Data!$B$2:$B$463,A10,Data!$AA$2:$AA$463,"full access") -> 0
A11: Sub-Saharan Africa | B11: =COUNTIFS(Data!$B$2:$B$463,A11,Data!$R$2:$R$463,">=0") -> 53 | C11: =SUMPRODUCT((Data!$B$2:$B$463=A11)*NOT(ISNUMBER(Data!$R$2:$R$463))*Data!$D$2:$D$463)/1000 -> 1124.0302 | D11: =IFERROR(AVERAGEIF(Data!$B$2:$B$463,A11,Data!$S$2:$S$463),"") -> 0.55936939 | E11: =IFERROR(AVERAGEIF(Data!$B$2:$B$463,A11,Data!$T$2:$T$463),"") -> 0.60408381 | F11: =IFERROR(AVERAGEIF(Data!$B$2:$B$463,A11,Data!$U$2:$U$463),"") -> 0.26903405 | G11: =COUNTIFS(Data!$B$2:$B$463,A11,Data!$Y$2:$Y$463,"full access") -> 2 | H11: =COUNTIFS(Data!$B$2:$B$463,A11,Data!$Z$2:$Z$463,"full access") -> 1 | I11: =COUNTIFS(Data!$B$2:$B$463,A11,Data!$AA$2:$AA$463,"full access") -> 1
A12: All regions | B12: =SUM(B5:B11) -> 231 | C12: =SUM(C5:C11) -> 7793.8175 | D12: =AVERAGE(Data!$S$2:$S$463) -> 0.27699608 | E12: =AVERAGE(Data!$T$2:$T$463) -> 0.48445493 | F12: =AVERAGE(Data!$U$2:$U$463) -> 0.15446264 | G12: =SUM(G5:G11) -> 62 | H12: =SUM(H5:H11) -> 29 | I12: =SUM(I5:I11) -> 55

Sheet Chart Data
A1: Data for the bubble chart (one row per country with both ARCs; values linked to the Data sheet)
A2: Country | B2: Region | C2: ARC – national | D2: ARC – rural | E2: Population (millions)
A3: =Data!A24 -> Australia | B3: =Data!B24 -> East Asia & Pacific | C3: =Data!S24 -> -3.877e-05 | D3: =Data!T24 -> 0 | E3: =Data!D25/1000 -> 25.499881
A4: =Data!A70 -> Cambodia | B4: =Data!B70 -> East Asia & Pacific | C4: =Data!S70 -> 0.5552072 | D4: =Data!T70 -> 0.47120783 | E4: =Data!D71/1000 -> 16.718971
A5: =Data!A86 -> China | B5: =Data!B86 -> East Asia & Pacific | C5: =Data!S86 -> 0.49969387 | D5: =Data!T86 -> 1.0364091 | E5: =Data!D87/1000 -> 1463.1405
A6: =Data!A114 -> Democratic People's Republic of Korea | B6: =Data!B114 -> East Asia & Pacific | C6: =Data!S114 -> -0.27420774 | D6: =Data!T114 -> -0.57266871 | E6: =Data!D115/1000 -> 25.778814
A7: =Data!A146 -> Fiji | B7: =Data!B146 -> East Asia & Pacific | C7: =Data!S146 -> 0.007701314 | D7: =Data!T146 -> -0.058100668 | E7: =Data!D147/1000 -> 0.89644397
A8: =Data!A196 -> Indonesia | B8: =Data!B196 -> East Asia & Pacific | C8: =Data!S196 -> 0.77759933 | D8: =Data!T196 -> 1.0074342 | E8: =Data!D197/1000 -> 273.52362
A9: =Data!A220 -> Kiribati | B9: =Data!B220 -> East Asia & Pacific | C9: =Data!S220 -> 0.82456485 | D9: =Data!T220 -> 0.61438646 | E9: =Data!D221/1000 -> 0.119446
A10: =Data!A226 -> Lao People's Democratic Republic | B10: =Data!B226 -> East Asia & Pacific | C10: =Data!S226 -> 1.5518342 | D10: =Data!T226 -> 1.6466546 | E10: =Data!D227/1000 -> 7.2755562
A11: =Data!A256 -> Marshall Islands | B11: =Data!B256 -> East Asia & Pacific | C11: =Data!S256 -> 0.045904672 | D11: =Data!T256 -> 0.030272 | E11: =Data!D257/1000 -> 0.059194
A12: =Data!A272 -> Mongolia | B12: =Data!B272 -> East Asia & Pacific | C12: =Data!S272 -> 0.93652264 | D12: =Data!T272 -> 1.7953726 | E12: =Data!D273/1000 -> 3.278292
A13: =Data!A282 -> Myanmar | B13: =Data!B282 -> East Asia & Pacific | C13: =Data!S282 -> 2.0261443 | D13: =Data!T282 -> 2.2345902 | E13: =Data!D283/1000 -> 54.409793
A14: =Data!A294 -> New Zealand | B14: =Data!B294 -> East Asia & Pacific | C14: =Data!S294 -> 7.9e-07 | D14: =Data!T294 -> 0 | E14: =Data!D295/1000 -> 4.8222329
A15: =Data!A314 -> Palau | B15: =Data!B314 -> East Asia & Pacific | C15: =Data!S314 -> 0.00547893 | D15: =Data!T314 -> 0.02862271 | E15: =Data!D315/1000 -> 0.018091999
A16: =Data!A318 -> Papua New Guinea | B16: =Data!B318 -> East Asia & Pacific | C16: =Data!S318 -> 0.77170182 | D16: =Data!T318 -> 0.81614213 | E16: =Data!D319/1000 -> 8.9470273
A17: =Data!A360 -> Samoa | B17: =Data!B360 -> East Asia & Pacific | C17: =Data!S360 -> 0.10326544 | D17: =Data!T360 -> 0.078781444 | E17: =Data!D361/1000 -> 0.19841
A18: =Data!A384 -> Solomon Islands | B18: =Data!B384 -> East Asia & Pacific | C18: =Data!S384 -> -0.40577867 | D18: =Data!T384 -> -0.72137414 | E18: =Data!D385/1000 -> 0.68687799
A19: =Data!A408 -> Thailand | B19: =Data!B408 -> East Asia & Pacific | C19: =Data!S408 -> 0.14816588 | D19: =Data!T408 -> 0.22409666 | E19: =Data!D409/1000 -> 69.799977
A20: =Data!A410 -> Timor-Leste | B20: =Data!B410 -> East Asia & Pacific | C20: =Data!S410 -> 2.0490995 | D20: =Data!T410 -> 2.3056812 | E20: =Data!D411/1000 -> 1.318442
A21: =Data!A414 -> Tokelau | B21: =Data!B414 -> East Asia & Pacific | C21: =Data!S414 -> 0.05005613 | D21: =Data!T414 -> 0.05005613 | E21: =Data!D415/1000 -> 0.00135
A22: =Data!A416 -> Tonga | B22: =Data!B416 -> East Asia & Pacific | C22: =Data!S416 -> 0.036275096 | D22: =Data!T416 -> 0.015006062 | E22: =Data!D417/1000 -> 0.105697
A23: =Data!A428 -> Tuvalu | B23: =Data!B428 -> East Asia & Pacific | C23: =Data!S428 -> 0 | D23: =Data!T428 -> 0 | E23: =Data!D429/1000 -> 0.011792
A24: =Data!A448 -> Vanuatu | B24: =Data!B448 -> East Asia & Pacific | C24: =Data!S448 -> 0.24860285 | D24: =Data!T448 -> 0.28383011 | E24: =Data!D449/1000 -> 0.30714999
A25: =Data!A452 -> Viet Nam | B25: =Data!B452 -> East Asia & Pacific | C25: =Data!S452 -> 0.71125926 | D25: =Data!T452 -> 0.93629409 | E25: =Data!D453/1000 -> 97.338586
A26: =Data!A454 -> Wallis and Futuna Islands | B26: =Data!B454 -> East Asia & Pacific | C26: =Data!S454 -> -0.035618834 | D26: =Data!T454 -> -0.035618834 | E26: =Data!D455/1000 -> 0.011246
A27: =Data!A4 -> Albania | B27: =Data!B4 -> Europe & Central Asia | C27: =Data!S4 -> 0.3347427 | D27: =Data!T4 -> 0.69281669 | E27: =Data!D5/1000 -> 2.8778
A28: =Data!A10 -> Andorra | B28: =Data!B10 -> Europe & Central Asia | C28: =Data!S10 -> 1.23e-06 | D28: =Data!T10 -> 0 | E28: =Data!D11/1000 -> 0.077264999
A29: =Data!A20 -> Armenia | B29: =Data!B20 -> Europe & Central Asia | C29: =Data!S20 -> 0.083722798 | D29: =Data!T20 -> 0.18904415 | E29: =Data!D21/1000 -> 2.9632339
A30: =Data!A26 -> Austria | B30: =Data!B26 -> Europe & Central Asia | C30: =Data!S26 -> 0 | D30: =Data!T26 -> 0 | E30: =Data!D27/1000 -> 9.0064004
A31: =Data!A28 -> Azerbaijan | B31: =Data!B28 -> Europe & Central Asia | C31: =Data!S28 -> 0.72461243 | D31: =Data!T28 -> 1.3565169 | E31: =Data!D29/1000 -> 10.139175
A32: =Data!A38 -> Belarus | B32: =Data!B38 -> Europe & Central Asia | C32: =Data!S38 -> 0.011531798 | D32: =Data!T38 -> 0.046690142 | E32: =Data!D39/1000 -> 9.4493213
A33: =Data!A40 -> Belgium | B33: =Data!B40 -> Europe & Central Asia | C33: =Data!S40 -> -2.5e-07 | D33: =Data!T40 -> 0 | E33: =Data!D41/1000 -> 11.589616
A34: =Data!A52 -> Bosnia and Herzegovina | B34: =Data!B52 -> Europe & Central Asia | C34: =Data!S52 -> -0.009189312 | D34: =Data!T52 -> 0 | E34: =Data!D53/1000 -> 3.2808149
A35: =Data!A62 -> Bulgaria | B35: =Data!B62 -> Europe & Central Asia | C35: =Data!S62 -> -0.036982074 | D35: =Data!T62 -> -0.12297047 | E35: =Data!D63/1000 -> 6.9484448
A36: =Data!A110 -> Cyprus | B36: =Data!B110 -> Europe & Central Asia | C36: =Data!S110 -> -0.004668878 | D36: =Data!T110 -> -0.003084764 | E36: =Data!D111/1000 -> 1.207361
A37: =Data!A112 -> Czech Republic | B37: =Data!B112 -> Europe & Central Asia | C37: =Data!S112 -> 9.9796e-05 | D37: =Data!T112 -> 0 | E37: =Data!D113/1000 -> 10.708982
A38: =Data!A118 -> Denmark | B38: =Data!B118 -> Europe & Central Asia | C38: =Data!S118 -> 6.5e-07 | D38: =Data!T118 -> 0 | E38: =Data!D119/1000 -> 5.7922031
A39: =Data!A148 -> Finland | B39: =Data!B148 -> Europe & Central Asia | C39: =Data!S148 -> 1.328e-06 | D39: =Data!T148 -> 0 | E39: =Data!D149/1000 -> 5.5407178
A40: =Data!A150 -> France | B40: =Data!B150 -> Europe & Central Asia | C40: =Data!S150 -> -3e-07 | D40: =Data!T150 -> 0 | E40: =Data!D151/1000 -> 65.273512
...

Sheet Region Lookup
A1: Country | B1: Region
A2: Afghanistan | B2: South Asia
A3: Albania | B3: Europe & Central Asia
A4: Algeria | B4: Middle East & North Africa
A5: American Samoa | B5: East Asia & Pacific
A6: Andorra | B6: Europe & Central Asia
A7: Angola | B7: Sub-Saharan Africa
A8: Anguilla | B8: Latin America & Caribbean
A9: Antigua and Barbuda | B9: Latin America & Caribbean
A10: Argentina | B10: Latin America & Caribbean
A11: Armenia | B11: Europe & Central Asia
A12: Aruba | B12: Latin America & Caribbean
